2017-08-13 21:27:54  concurrent.futures ERROR      exception calling callback for <Future at 0x1fcbe8642b0 state=finished raised Exception>
Traceback (most recent call last):
  File "scraper_nbareference_multiprocess.py", line 121, in scrapy_regular_team_data
    trs = tbody.find_all('tr')
AttributeError: 'NoneType' object has no attribute 'find_all'

During handling of the above exception, another exception occurred:

Traceback (most recent call last):
  File "C:\Users\xiyang\AppData\Local\Programs\Python\Python35\lib\concurrent\futures\_base.py", line 297, in _invoke_callbacks
    callback(self)
  File "scraper_nbareference_multiprocess.py", line 158, in output_regular_team_data
    data, games, season = future.result()
  File "C:\Users\xiyang\AppData\Local\Programs\Python\Python35\lib\concurrent\futures\_base.py", line 398, in result
    return self.__get_result()
  File "C:\Users\xiyang\AppData\Local\Programs\Python\Python35\lib\concurrent\futures\_base.py", line 357, in __get_result
    raise self._exception
  File "C:\Users\xiyang\AppData\Local\Programs\Python\Python35\lib\concurrent\futures\thread.py", line 55, in run
    result = self.fn(*self.args, **self.kwargs)
  File "scraper_nbareference_multiprocess.py", line 151, in scrapy_regular_team_data
    raise Exception(e)
Exception: 'NoneType' object has no attribute 'find_all'
2017-08-13 21:27:54  concurrent.futures ERROR      exception calling callback for <Future at 0x1fcbe85aef0 state=finished raised Exception>
Traceback (most recent call last):
  File "scraper_nbareference_multiprocess.py", line 121, in scrapy_regular_team_data
    trs = tbody.find_all('tr')
AttributeError: 'NoneType' object has no attribute 'find_all'

During handling of the above exception, another exception occurred:

Traceback (most recent call last):
  File "C:\Users\xiyang\AppData\Local\Programs\Python\Python35\lib\concurrent\futures\_base.py", line 297, in _invoke_callbacks
    callback(self)
  File "scraper_nbareference_multiprocess.py", line 158, in output_regular_team_data
    data, games, season = future.result()
  File "C:\Users\xiyang\AppData\Local\Programs\Python\Python35\lib\concurrent\futures\_base.py", line 398, in result
    return self.__get_result()
  File "C:\Users\xiyang\AppData\Local\Programs\Python\Python35\lib\concurrent\futures\_base.py", line 357, in __get_result
    raise self._exception
  File "C:\Users\xiyang\AppData\Local\Programs\Python\Python35\lib\concurrent\futures\thread.py", line 55, in run
    result = self.fn(*self.args, **self.kwargs)
  File "scraper_nbareference_multiprocess.py", line 151, in scrapy_regular_team_data
    raise Exception(e)
Exception: 'NoneType' object has no attribute 'find_all'
2017-08-13 21:27:56  concurrent.futures ERROR      exception calling callback for <Future at 0x1fcbe8640f0 state=finished raised Exception>
Traceback (most recent call last):
  File "scraper_nbareference_multiprocess.py", line 121, in scrapy_regular_team_data
    trs = tbody.find_all('tr')
AttributeError: 'NoneType' object has no attribute 'find_all'

During handling of the above exception, another exception occurred:

Traceback (most recent call last):
  File "C:\Users\xiyang\AppData\Local\Programs\Python\Python35\lib\concurrent\futures\_base.py", line 297, in _invoke_callbacks
    callback(self)
  File "scraper_nbareference_multiprocess.py", line 158, in output_regular_team_data
    data, games, season = future.result()
  File "C:\Users\xiyang\AppData\Local\Programs\Python\Python35\lib\concurrent\futures\_base.py", line 398, in result
    return self.__get_result()
  File "C:\Users\xiyang\AppData\Local\Programs\Python\Python35\lib\concurrent\futures\_base.py", line 357, in __get_result
    raise self._exception
  File "C:\Users\xiyang\AppData\Local\Programs\Python\Python35\lib\concurrent\futures\thread.py", line 55, in run
    result = self.fn(*self.args, **self.kwargs)
  File "scraper_nbareference_multiprocess.py", line 151, in scrapy_regular_team_data
    raise Exception(e)
Exception: 'NoneType' object has no attribute 'find_all'
2017-08-13 21:27:56  concurrent.futures ERROR      exception calling callback for <Future at 0x1fcbe85ada0 state=finished raised Exception>
Traceback (most recent call last):
  File "scraper_nbareference_multiprocess.py", line 121, in scrapy_regular_team_data
    trs = tbody.find_all('tr')
AttributeError: 'NoneType' object has no attribute 'find_all'

During handling of the above exception, another exception occurred:

Traceback (most recent call last):
  File "C:\Users\xiyang\AppData\Local\Programs\Python\Python35\lib\concurrent\futures\_base.py", line 297, in _invoke_callbacks
    callback(self)
  File "scraper_nbareference_multiprocess.py", line 158, in output_regular_team_data
    data, games, season = future.result()
  File "C:\Users\xiyang\AppData\Local\Programs\Python\Python35\lib\concurrent\futures\_base.py", line 398, in result
    return self.__get_result()
  File "C:\Users\xiyang\AppData\Local\Programs\Python\Python35\lib\concurrent\futures\_base.py", line 357, in __get_result
    raise self._exception
  File "C:\Users\xiyang\AppData\Local\Programs\Python\Python35\lib\concurrent\futures\thread.py", line 55, in run
    result = self.fn(*self.args, **self.kwargs)
  File "scraper_nbareference_multiprocess.py", line 151, in scrapy_regular_team_data
    raise Exception(e)
Exception: 'NoneType' object has no attribute 'find_all'
2017-08-13 21:27:58  concurrent.futures ERROR      exception calling callback for <Future at 0x1fcbe864470 state=finished raised Exception>
Traceback (most recent call last):
  File "scraper_nbareference_multiprocess.py", line 121, in scrapy_regular_team_data
    trs = tbody.find_all('tr')
AttributeError: 'NoneType' object has no attribute 'find_all'

During handling of the above exception, another exception occurred:

Traceback (most recent call last):
  File "C:\Users\xiyang\AppData\Local\Programs\Python\Python35\lib\concurrent\futures\_base.py", line 297, in _invoke_callbacks
    callback(self)
  File "scraper_nbareference_multiprocess.py", line 158, in output_regular_team_data
    data, games, season = future.result()
  File "C:\Users\xiyang\AppData\Local\Programs\Python\Python35\lib\concurrent\futures\_base.py", line 398, in result
    return self.__get_result()
  File "C:\Users\xiyang\AppData\Local\Programs\Python\Python35\lib\concurrent\futures\_base.py", line 357, in __get_result
    raise self._exception
  File "C:\Users\xiyang\AppData\Local\Programs\Python\Python35\lib\concurrent\futures\thread.py", line 55, in run
    result = self.fn(*self.args, **self.kwargs)
  File "scraper_nbareference_multiprocess.py", line 151, in scrapy_regular_team_data
    raise Exception(e)
Exception: 'NoneType' object has no attribute 'find_all'
2017-08-13 21:27:58  concurrent.futures ERROR      exception calling callback for <Future at 0x1fcbe864518 state=finished raised Exception>
Traceback (most recent call last):
  File "scraper_nbareference_multiprocess.py", line 121, in scrapy_regular_team_data
    trs = tbody.find_all('tr')
AttributeError: 'NoneType' object has no attribute 'find_all'

During handling of the above exception, another exception occurred:

Traceback (most recent call last):
  File "C:\Users\xiyang\AppData\Local\Programs\Python\Python35\lib\concurrent\futures\_base.py", line 297, in _invoke_callbacks
    callback(self)
  File "scraper_nbareference_multiprocess.py", line 158, in output_regular_team_data
    data, games, season = future.result()
  File "C:\Users\xiyang\AppData\Local\Programs\Python\Python35\lib\concurrent\futures\_base.py", line 398, in result
    return self.__get_result()
  File "C:\Users\xiyang\AppData\Local\Programs\Python\Python35\lib\concurrent\futures\_base.py", line 357, in __get_result
    raise self._exception
  File "C:\Users\xiyang\AppData\Local\Programs\Python\Python35\lib\concurrent\futures\thread.py", line 55, in run
    result = self.fn(*self.args, **self.kwargs)
  File "scraper_nbareference_multiprocess.py", line 151, in scrapy_regular_team_data
    raise Exception(e)
Exception: 'NoneType' object has no attribute 'find_all'
2017-08-13 21:27:59  concurrent.futures ERROR      exception calling callback for <Future at 0x1fcbe8645c0 state=finished raised Exception>
Traceback (most recent call last):
  File "scraper_nbareference_multiprocess.py", line 121, in scrapy_regular_team_data
    trs = tbody.find_all('tr')
AttributeError: 'NoneType' object has no attribute 'find_all'

During handling of the above exception, another exception occurred:

Traceback (most recent call last):
  File "C:\Users\xiyang\AppData\Local\Programs\Python\Python35\lib\concurrent\futures\_base.py", line 297, in _invoke_callbacks
    callback(self)
  File "scraper_nbareference_multiprocess.py", line 158, in output_regular_team_data
    data, games, season = future.result()
  File "C:\Users\xiyang\AppData\Local\Programs\Python\Python35\lib\concurrent\futures\_base.py", line 398, in result
    return self.__get_result()
  File "C:\Users\xiyang\AppData\Local\Programs\Python\Python35\lib\concurrent\futures\_base.py", line 357, in __get_result
    raise self._exception
  File "C:\Users\xiyang\AppData\Local\Programs\Python\Python35\lib\concurrent\futures\thread.py", line 55, in run
    result = self.fn(*self.args, **self.kwargs)
  File "scraper_nbareference_multiprocess.py", line 151, in scrapy_regular_team_data
    raise Exception(e)
Exception: 'NoneType' object has no attribute 'find_all'
2017-08-13 21:28:01  concurrent.futures ERROR      exception calling callback for <Future at 0x1fcbfb782e8 state=finished raised Exception>
Traceback (most recent call last):
  File "scraper_nbareference_multiprocess.py", line 121, in scrapy_regular_team_data
    trs = tbody.find_all('tr')
AttributeError: 'NoneType' object has no attribute 'find_all'

During handling of the above exception, another exception occurred:

Traceback (most recent call last):
  File "C:\Users\xiyang\AppData\Local\Programs\Python\Python35\lib\concurrent\futures\_base.py", line 297, in _invoke_callbacks
    callback(self)
  File "scraper_nbareference_multiprocess.py", line 158, in output_regular_team_data
    data, games, season = future.result()
  File "C:\Users\xiyang\AppData\Local\Programs\Python\Python35\lib\concurrent\futures\_base.py", line 398, in result
    return self.__get_result()
  File "C:\Users\xiyang\AppData\Local\Programs\Python\Python35\lib\concurrent\futures\_base.py", line 357, in __get_result
    raise self._exception
  File "C:\Users\xiyang\AppData\Local\Programs\Python\Python35\lib\concurrent\futures\thread.py", line 55, in run
    result = self.fn(*self.args, **self.kwargs)
  File "scraper_nbareference_multiprocess.py", line 151, in scrapy_regular_team_data
    raise Exception(e)
Exception: 'NoneType' object has no attribute 'find_all'
2017-08-13 21:28:02  concurrent.futures ERROR      exception calling callback for <Future at 0x1fcbfb78240 state=finished raised Exception>
Traceback (most recent call last):
  File "scraper_nbareference_multiprocess.py", line 121, in scrapy_regular_team_data
    trs = tbody.find_all('tr')
AttributeError: 'NoneType' object has no attribute 'find_all'

During handling of the above exception, another exception occurred:

Traceback (most recent call last):
  File "C:\Users\xiyang\AppData\Local\Programs\Python\Python35\lib\concurrent\futures\_base.py", line 297, in _invoke_callbacks
    callback(self)
  File "scraper_nbareference_multiprocess.py", line 158, in output_regular_team_data
    data, games, season = future.result()
  File "C:\Users\xiyang\AppData\Local\Programs\Python\Python35\lib\concurrent\futures\_base.py", line 398, in result
    return self.__get_result()
  File "C:\Users\xiyang\AppData\Local\Programs\Python\Python35\lib\concurrent\futures\_base.py", line 357, in __get_result
    raise self._exception
  File "C:\Users\xiyang\AppData\Local\Programs\Python\Python35\lib\concurrent\futures\thread.py", line 55, in run
    result = self.fn(*self.args, **self.kwargs)
  File "scraper_nbareference_multiprocess.py", line 151, in scrapy_regular_team_data
    raise Exception(e)
Exception: 'NoneType' object has no attribute 'find_all'
2017-08-13 21:28:03  concurrent.futures ERROR      exception calling callback for <Future at 0x1fcbfb78438 state=finished raised Exception>
Traceback (most recent call last):
  File "scraper_nbareference_multiprocess.py", line 121, in scrapy_regular_team_data
    trs = tbody.find_all('tr')
AttributeError: 'NoneType' object has no attribute 'find_all'

During handling of the above exception, another exception occurred:

Traceback (most recent call last):
  File "C:\Users\xiyang\AppData\Local\Programs\Python\Python35\lib\concurrent\futures\_base.py", line 297, in _invoke_callbacks
    callback(self)
  File "scraper_nbareference_multiprocess.py", line 158, in output_regular_team_data
    data, games, season = future.result()
  File "C:\Users\xiyang\AppData\Local\Programs\Python\Python35\lib\concurrent\futures\_base.py", line 398, in result
    return self.__get_result()
  File "C:\Users\xiyang\AppData\Local\Programs\Python\Python35\lib\concurrent\futures\_base.py", line 357, in __get_result
    raise self._exception
  File "C:\Users\xiyang\AppData\Local\Programs\Python\Python35\lib\concurrent\futures\thread.py", line 55, in run
    result = self.fn(*self.args, **self.kwargs)
  File "scraper_nbareference_multiprocess.py", line 151, in scrapy_regular_team_data
    raise Exception(e)
Exception: 'NoneType' object has no attribute 'find_all'
2017-08-13 21:28:04  concurrent.futures ERROR      exception calling callback for <Future at 0x1fcbfb78390 state=finished raised Exception>
Traceback (most recent call last):
  File "scraper_nbareference_multiprocess.py", line 121, in scrapy_regular_team_data
    trs = tbody.find_all('tr')
AttributeError: 'NoneType' object has no attribute 'find_all'

During handling of the above exception, another exception occurred:

Traceback (most recent call last):
  File "C:\Users\xiyang\AppData\Local\Programs\Python\Python35\lib\concurrent\futures\_base.py", line 297, in _invoke_callbacks
    callback(self)
  File "scraper_nbareference_multiprocess.py", line 158, in output_regular_team_data
    data, games, season = future.result()
  File "C:\Users\xiyang\AppData\Local\Programs\Python\Python35\lib\concurrent\futures\_base.py", line 398, in result
    return self.__get_result()
  File "C:\Users\xiyang\AppData\Local\Programs\Python\Python35\lib\concurrent\futures\_base.py", line 357, in __get_result
    raise self._exception
  File "C:\Users\xiyang\AppData\Local\Programs\Python\Python35\lib\concurrent\futures\thread.py", line 55, in run
    result = self.fn(*self.args, **self.kwargs)
  File "scraper_nbareference_multiprocess.py", line 151, in scrapy_regular_team_data
    raise Exception(e)
Exception: 'NoneType' object has no attribute 'find_all'
2017-08-13 21:28:05  concurrent.futures ERROR      exception calling callback for <Future at 0x1fcbfb784e0 state=finished raised Exception>
Traceback (most recent call last):
  File "scraper_nbareference_multiprocess.py", line 121, in scrapy_regular_team_data
    trs = tbody.find_all('tr')
AttributeError: 'NoneType' object has no attribute 'find_all'

During handling of the above exception, another exception occurred:

Traceback (most recent call last):
  File "C:\Users\xiyang\AppData\Local\Programs\Python\Python35\lib\concurrent\futures\_base.py", line 297, in _invoke_callbacks
    callback(self)
  File "scraper_nbareference_multiprocess.py", line 158, in output_regular_team_data
    data, games, season = future.result()
  File "C:\Users\xiyang\AppData\Local\Programs\Python\Python35\lib\concurrent\futures\_base.py", line 398, in result
    return self.__get_result()
  File "C:\Users\xiyang\AppData\Local\Programs\Python\Python35\lib\concurrent\futures\_base.py", line 357, in __get_result
    raise self._exception
  File "C:\Users\xiyang\AppData\Local\Programs\Python\Python35\lib\concurrent\futures\thread.py", line 55, in run
    result = self.fn(*self.args, **self.kwargs)
  File "scraper_nbareference_multiprocess.py", line 151, in scrapy_regular_team_data
    raise Exception(e)
Exception: 'NoneType' object has no attribute 'find_all'
2017-08-13 21:28:06  concurrent.futures ERROR      exception calling callback for <Future at 0x1fcbfb78588 state=finished raised Exception>
Traceback (most recent call last):
  File "scraper_nbareference_multiprocess.py", line 121, in scrapy_regular_team_data
    trs = tbody.find_all('tr')
AttributeError: 'NoneType' object has no attribute 'find_all'

During handling of the above exception, another exception occurred:

Traceback (most recent call last):
  File "C:\Users\xiyang\AppData\Local\Programs\Python\Python35\lib\concurrent\futures\_base.py", line 297, in _invoke_callbacks
    callback(self)
  File "scraper_nbareference_multiprocess.py", line 158, in output_regular_team_data
    data, games, season = future.result()
  File "C:\Users\xiyang\AppData\Local\Programs\Python\Python35\lib\concurrent\futures\_base.py", line 398, in result
    return self.__get_result()
  File "C:\Users\xiyang\AppData\Local\Programs\Python\Python35\lib\concurrent\futures\_base.py", line 357, in __get_result
    raise self._exception
  File "C:\Users\xiyang\AppData\Local\Programs\Python\Python35\lib\concurrent\futures\thread.py", line 55, in run
    result = self.fn(*self.args, **self.kwargs)
  File "scraper_nbareference_multiprocess.py", line 151, in scrapy_regular_team_data
    raise Exception(e)
Exception: 'NoneType' object has no attribute 'find_all'
2017-08-13 21:28:07  concurrent.futures ERROR      exception calling callback for <Future at 0x1fcbfb78630 state=finished raised Exception>
Traceback (most recent call last):
  File "scraper_nbareference_multiprocess.py", line 121, in scrapy_regular_team_data
    trs = tbody.find_all('tr')
AttributeError: 'NoneType' object has no attribute 'find_all'

During handling of the above exception, another exception occurred:

Traceback (most recent call last):
  File "C:\Users\xiyang\AppData\Local\Programs\Python\Python35\lib\concurrent\futures\_base.py", line 297, in _invoke_callbacks
    callback(self)
  File "scraper_nbareference_multiprocess.py", line 158, in output_regular_team_data
    data, games, season = future.result()
  File "C:\Users\xiyang\AppData\Local\Programs\Python\Python35\lib\concurrent\futures\_base.py", line 398, in result
    return self.__get_result()
  File "C:\Users\xiyang\AppData\Local\Programs\Python\Python35\lib\concurrent\futures\_base.py", line 357, in __get_result
    raise self._exception
  File "C:\Users\xiyang\AppData\Local\Programs\Python\Python35\lib\concurrent\futures\thread.py", line 55, in run
    result = self.fn(*self.args, **self.kwargs)
  File "scraper_nbareference_multiprocess.py", line 151, in scrapy_regular_team_data
    raise Exception(e)
Exception: 'NoneType' object has no attribute 'find_all'
2017-08-13 21:31:49  concurrent.futures ERROR      exception calling callback for <Future at 0x2210f4eaf60 state=finished raised Exception>
Traceback (most recent call last):
  File "scraper_nbareference_multiprocess.py", line 124, in scrapy_regular_team_data
    if os.stat(file).st_size == 0:
FileNotFoundError: [WinError 2] The system cannot find the file specified: 'data/regular_season_team_data_2011.csv'

During handling of the above exception, another exception occurred:

Traceback (most recent call last):
  File "C:\Users\xiyang\AppData\Local\Programs\Python\Python35\lib\concurrent\futures\_base.py", line 297, in _invoke_callbacks
    callback(self)
  File "scraper_nbareference_multiprocess.py", line 158, in output_regular_team_data
    data, games, season = future.result()
  File "C:\Users\xiyang\AppData\Local\Programs\Python\Python35\lib\concurrent\futures\_base.py", line 398, in result
    return self.__get_result()
  File "C:\Users\xiyang\AppData\Local\Programs\Python\Python35\lib\concurrent\futures\_base.py", line 357, in __get_result
    raise self._exception
  File "C:\Users\xiyang\AppData\Local\Programs\Python\Python35\lib\concurrent\futures\thread.py", line 55, in run
    result = self.fn(*self.args, **self.kwargs)
  File "scraper_nbareference_multiprocess.py", line 151, in scrapy_regular_team_data
    raise Exception(e)
Exception: [WinError 2] The system cannot find the file specified: 'data/regular_season_team_data_2011.csv'
2017-08-13 21:31:50  concurrent.futures ERROR      exception calling callback for <Future at 0x2210f4eae10 state=finished raised Exception>
Traceback (most recent call last):
  File "scraper_nbareference_multiprocess.py", line 124, in scrapy_regular_team_data
    if os.stat(file).st_size == 0:
FileNotFoundError: [WinError 2] The system cannot find the file specified: 'data/regular_season_team_data_2011.csv'

During handling of the above exception, another exception occurred:

Traceback (most recent call last):
  File "C:\Users\xiyang\AppData\Local\Programs\Python\Python35\lib\concurrent\futures\_base.py", line 297, in _invoke_callbacks
    callback(self)
  File "scraper_nbareference_multiprocess.py", line 158, in output_regular_team_data
    data, games, season = future.result()
  File "C:\Users\xiyang\AppData\Local\Programs\Python\Python35\lib\concurrent\futures\_base.py", line 398, in result
    return self.__get_result()
  File "C:\Users\xiyang\AppData\Local\Programs\Python\Python35\lib\concurrent\futures\_base.py", line 357, in __get_result
    raise self._exception
  File "C:\Users\xiyang\AppData\Local\Programs\Python\Python35\lib\concurrent\futures\thread.py", line 55, in run
    result = self.fn(*self.args, **self.kwargs)
  File "scraper_nbareference_multiprocess.py", line 151, in scrapy_regular_team_data
    raise Exception(e)
Exception: [WinError 2] The system cannot find the file specified: 'data/regular_season_team_data_2011.csv'
2017-08-13 21:31:51  concurrent.futures ERROR      exception calling callback for <Future at 0x2210f4f4160 state=finished raised Exception>
Traceback (most recent call last):
  File "scraper_nbareference_multiprocess.py", line 124, in scrapy_regular_team_data
    if os.stat(file).st_size == 0:
FileNotFoundError: [WinError 2] The system cannot find the file specified: 'data/regular_season_team_data_2011.csv'

During handling of the above exception, another exception occurred:

Traceback (most recent call last):
  File "C:\Users\xiyang\AppData\Local\Programs\Python\Python35\lib\concurrent\futures\_base.py", line 297, in _invoke_callbacks
    callback(self)
  File "scraper_nbareference_multiprocess.py", line 158, in output_regular_team_data
    data, games, season = future.result()
  File "C:\Users\xiyang\AppData\Local\Programs\Python\Python35\lib\concurrent\futures\_base.py", line 398, in result
    return self.__get_result()
  File "C:\Users\xiyang\AppData\Local\Programs\Python\Python35\lib\concurrent\futures\_base.py", line 357, in __get_result
    raise self._exception
  File "C:\Users\xiyang\AppData\Local\Programs\Python\Python35\lib\concurrent\futures\thread.py", line 55, in run
    result = self.fn(*self.args, **self.kwargs)
  File "scraper_nbareference_multiprocess.py", line 151, in scrapy_regular_team_data
    raise Exception(e)
Exception: [WinError 2] The system cannot find the file specified: 'data/regular_season_team_data_2011.csv'
2017-08-13 21:31:52  concurrent.futures ERROR      exception calling callback for <Future at 0x2210f4f4320 state=finished raised Exception>
Traceback (most recent call last):
  File "scraper_nbareference_multiprocess.py", line 124, in scrapy_regular_team_data
    if os.stat(file).st_size == 0:
FileNotFoundError: [WinError 2] The system cannot find the file specified: 'data/regular_season_team_data_2011.csv'

During handling of the above exception, another exception occurred:

Traceback (most recent call last):
  File "C:\Users\xiyang\AppData\Local\Programs\Python\Python35\lib\concurrent\futures\_base.py", line 297, in _invoke_callbacks
    callback(self)
  File "scraper_nbareference_multiprocess.py", line 158, in output_regular_team_data
    data, games, season = future.result()
  File "C:\Users\xiyang\AppData\Local\Programs\Python\Python35\lib\concurrent\futures\_base.py", line 398, in result
    return self.__get_result()
  File "C:\Users\xiyang\AppData\Local\Programs\Python\Python35\lib\concurrent\futures\_base.py", line 357, in __get_result
    raise self._exception
  File "C:\Users\xiyang\AppData\Local\Programs\Python\Python35\lib\concurrent\futures\thread.py", line 55, in run
    result = self.fn(*self.args, **self.kwargs)
  File "scraper_nbareference_multiprocess.py", line 151, in scrapy_regular_team_data
    raise Exception(e)
Exception: [WinError 2] The system cannot find the file specified: 'data/regular_season_team_data_2011.csv'
2017-08-13 21:31:53  concurrent.futures ERROR      exception calling callback for <Future at 0x2210f4f44e0 state=finished raised Exception>
Traceback (most recent call last):
  File "scraper_nbareference_multiprocess.py", line 124, in scrapy_regular_team_data
    if os.stat(file).st_size == 0:
FileNotFoundError: [WinError 2] The system cannot find the file specified: 'data/regular_season_team_data_2011.csv'

During handling of the above exception, another exception occurred:

Traceback (most recent call last):
  File "C:\Users\xiyang\AppData\Local\Programs\Python\Python35\lib\concurrent\futures\_base.py", line 297, in _invoke_callbacks
    callback(self)
  File "scraper_nbareference_multiprocess.py", line 158, in output_regular_team_data
    data, games, season = future.result()
  File "C:\Users\xiyang\AppData\Local\Programs\Python\Python35\lib\concurrent\futures\_base.py", line 398, in result
    return self.__get_result()
  File "C:\Users\xiyang\AppData\Local\Programs\Python\Python35\lib\concurrent\futures\_base.py", line 357, in __get_result
    raise self._exception
  File "C:\Users\xiyang\AppData\Local\Programs\Python\Python35\lib\concurrent\futures\thread.py", line 55, in run
    result = self.fn(*self.args, **self.kwargs)
  File "scraper_nbareference_multiprocess.py", line 151, in scrapy_regular_team_data
    raise Exception(e)
Exception: [WinError 2] The system cannot find the file specified: 'data/regular_season_team_data_2011.csv'
2017-08-13 21:31:54  concurrent.futures ERROR      exception calling callback for <Future at 0x2210f4f4588 state=finished raised Exception>
Traceback (most recent call last):
  File "scraper_nbareference_multiprocess.py", line 124, in scrapy_regular_team_data
    if os.stat(file).st_size == 0:
FileNotFoundError: [WinError 2] The system cannot find the file specified: 'data/regular_season_team_data_2011.csv'

During handling of the above exception, another exception occurred:

Traceback (most recent call last):
  File "C:\Users\xiyang\AppData\Local\Programs\Python\Python35\lib\concurrent\futures\_base.py", line 297, in _invoke_callbacks
    callback(self)
  File "scraper_nbareference_multiprocess.py", line 158, in output_regular_team_data
    data, games, season = future.result()
  File "C:\Users\xiyang\AppData\Local\Programs\Python\Python35\lib\concurrent\futures\_base.py", line 398, in result
    return self.__get_result()
  File "C:\Users\xiyang\AppData\Local\Programs\Python\Python35\lib\concurrent\futures\_base.py", line 357, in __get_result
    raise self._exception
  File "C:\Users\xiyang\AppData\Local\Programs\Python\Python35\lib\concurrent\futures\thread.py", line 55, in run
    result = self.fn(*self.args, **self.kwargs)
  File "scraper_nbareference_multiprocess.py", line 151, in scrapy_regular_team_data
    raise Exception(e)
Exception: [WinError 2] The system cannot find the file specified: 'data/regular_season_team_data_2011.csv'
2017-08-13 21:31:55  concurrent.futures ERROR      exception calling callback for <Future at 0x2210f4f4630 state=finished raised Exception>
Traceback (most recent call last):
  File "scraper_nbareference_multiprocess.py", line 124, in scrapy_regular_team_data
    if os.stat(file).st_size == 0:
FileNotFoundError: [WinError 2] The system cannot find the file specified: 'data/regular_season_team_data_2011.csv'

During handling of the above exception, another exception occurred:

Traceback (most recent call last):
  File "C:\Users\xiyang\AppData\Local\Programs\Python\Python35\lib\concurrent\futures\_base.py", line 297, in _invoke_callbacks
    callback(self)
  File "scraper_nbareference_multiprocess.py", line 158, in output_regular_team_data
    data, games, season = future.result()
  File "C:\Users\xiyang\AppData\Local\Programs\Python\Python35\lib\concurrent\futures\_base.py", line 398, in result
    return self.__get_result()
  File "C:\Users\xiyang\AppData\Local\Programs\Python\Python35\lib\concurrent\futures\_base.py", line 357, in __get_result
    raise self._exception
  File "C:\Users\xiyang\AppData\Local\Programs\Python\Python35\lib\concurrent\futures\thread.py", line 55, in run
    result = self.fn(*self.args, **self.kwargs)
  File "scraper_nbareference_multiprocess.py", line 151, in scrapy_regular_team_data
    raise Exception(e)
Exception: [WinError 2] The system cannot find the file specified: 'data/regular_season_team_data_2011.csv'
2017-08-13 21:31:56  concurrent.futures ERROR      exception calling callback for <Future at 0x2211249d240 state=finished raised Exception>
Traceback (most recent call last):
  File "scraper_nbareference_multiprocess.py", line 124, in scrapy_regular_team_data
    if os.stat(file).st_size == 0:
FileNotFoundError: [WinError 2] The system cannot find the file specified: 'data/regular_season_team_data_2012.csv'

During handling of the above exception, another exception occurred:

Traceback (most recent call last):
  File "C:\Users\xiyang\AppData\Local\Programs\Python\Python35\lib\concurrent\futures\_base.py", line 297, in _invoke_callbacks
    callback(self)
  File "scraper_nbareference_multiprocess.py", line 158, in output_regular_team_data
    data, games, season = future.result()
  File "C:\Users\xiyang\AppData\Local\Programs\Python\Python35\lib\concurrent\futures\_base.py", line 398, in result
    return self.__get_result()
  File "C:\Users\xiyang\AppData\Local\Programs\Python\Python35\lib\concurrent\futures\_base.py", line 357, in __get_result
    raise self._exception
  File "C:\Users\xiyang\AppData\Local\Programs\Python\Python35\lib\concurrent\futures\thread.py", line 55, in run
    result = self.fn(*self.args, **self.kwargs)
  File "scraper_nbareference_multiprocess.py", line 151, in scrapy_regular_team_data
    raise Exception(e)
Exception: [WinError 2] The system cannot find the file specified: 'data/regular_season_team_data_2012.csv'
2017-08-13 21:31:57  concurrent.futures ERROR      exception calling callback for <Future at 0x2211249d198 state=finished raised Exception>
Traceback (most recent call last):
  File "scraper_nbareference_multiprocess.py", line 121, in scrapy_regular_team_data
    trs = tbody.find_all('tr')
AttributeError: 'NoneType' object has no attribute 'find_all'

During handling of the above exception, another exception occurred:

Traceback (most recent call last):
  File "C:\Users\xiyang\AppData\Local\Programs\Python\Python35\lib\concurrent\futures\_base.py", line 297, in _invoke_callbacks
    callback(self)
  File "scraper_nbareference_multiprocess.py", line 158, in output_regular_team_data
    data, games, season = future.result()
  File "C:\Users\xiyang\AppData\Local\Programs\Python\Python35\lib\concurrent\futures\_base.py", line 398, in result
    return self.__get_result()
  File "C:\Users\xiyang\AppData\Local\Programs\Python\Python35\lib\concurrent\futures\_base.py", line 357, in __get_result
    raise self._exception
  File "C:\Users\xiyang\AppData\Local\Programs\Python\Python35\lib\concurrent\futures\thread.py", line 55, in run
    result = self.fn(*self.args, **self.kwargs)
  File "scraper_nbareference_multiprocess.py", line 151, in scrapy_regular_team_data
    raise Exception(e)
Exception: 'NoneType' object has no attribute 'find_all'
2017-08-13 21:31:58  concurrent.futures ERROR      exception calling callback for <Future at 0x2211249d0f0 state=finished raised Exception>
Traceback (most recent call last):
  File "scraper_nbareference_multiprocess.py", line 121, in scrapy_regular_team_data
    trs = tbody.find_all('tr')
AttributeError: 'NoneType' object has no attribute 'find_all'

During handling of the above exception, another exception occurred:

Traceback (most recent call last):
  File "C:\Users\xiyang\AppData\Local\Programs\Python\Python35\lib\concurrent\futures\_base.py", line 297, in _invoke_callbacks
    callback(self)
  File "scraper_nbareference_multiprocess.py", line 158, in output_regular_team_data
    data, games, season = future.result()
  File "C:\Users\xiyang\AppData\Local\Programs\Python\Python35\lib\concurrent\futures\_base.py", line 398, in result
    return self.__get_result()
  File "C:\Users\xiyang\AppData\Local\Programs\Python\Python35\lib\concurrent\futures\_base.py", line 357, in __get_result
    raise self._exception
  File "C:\Users\xiyang\AppData\Local\Programs\Python\Python35\lib\concurrent\futures\thread.py", line 55, in run
    result = self.fn(*self.args, **self.kwargs)
  File "scraper_nbareference_multiprocess.py", line 151, in scrapy_regular_team_data
    raise Exception(e)
Exception: 'NoneType' object has no attribute 'find_all'
2017-08-13 21:32:00  concurrent.futures ERROR      exception calling callback for <Future at 0x2211249d2e8 state=finished raised Exception>
Traceback (most recent call last):
  File "scraper_nbareference_multiprocess.py", line 124, in scrapy_regular_team_data
    if os.stat(file).st_size == 0:
FileNotFoundError: [WinError 2] The system cannot find the file specified: 'data/regular_season_team_data_2012.csv'

During handling of the above exception, another exception occurred:

Traceback (most recent call last):
  File "C:\Users\xiyang\AppData\Local\Programs\Python\Python35\lib\concurrent\futures\_base.py", line 297, in _invoke_callbacks
    callback(self)
  File "scraper_nbareference_multiprocess.py", line 158, in output_regular_team_data
    data, games, season = future.result()
  File "C:\Users\xiyang\AppData\Local\Programs\Python\Python35\lib\concurrent\futures\_base.py", line 398, in result
    return self.__get_result()
  File "C:\Users\xiyang\AppData\Local\Programs\Python\Python35\lib\concurrent\futures\_base.py", line 357, in __get_result
    raise self._exception
  File "C:\Users\xiyang\AppData\Local\Programs\Python\Python35\lib\concurrent\futures\thread.py", line 55, in run
    result = self.fn(*self.args, **self.kwargs)
  File "scraper_nbareference_multiprocess.py", line 151, in scrapy_regular_team_data
    raise Exception(e)
Exception: [WinError 2] The system cannot find the file specified: 'data/regular_season_team_data_2012.csv'
2017-08-13 21:32:01  concurrent.futures ERROR      exception calling callback for <Future at 0x2211249d390 state=finished raised Exception>
Traceback (most recent call last):
  File "scraper_nbareference_multiprocess.py", line 124, in scrapy_regular_team_data
    if os.stat(file).st_size == 0:
FileNotFoundError: [WinError 2] The system cannot find the file specified: 'data/regular_season_team_data_2012.csv'

During handling of the above exception, another exception occurred:

Traceback (most recent call last):
  File "C:\Users\xiyang\AppData\Local\Programs\Python\Python35\lib\concurrent\futures\_base.py", line 297, in _invoke_callbacks
    callback(self)
  File "scraper_nbareference_multiprocess.py", line 158, in output_regular_team_data
    data, games, season = future.result()
  File "C:\Users\xiyang\AppData\Local\Programs\Python\Python35\lib\concurrent\futures\_base.py", line 398, in result
    return self.__get_result()
  File "C:\Users\xiyang\AppData\Local\Programs\Python\Python35\lib\concurrent\futures\_base.py", line 357, in __get_result
    raise self._exception
  File "C:\Users\xiyang\AppData\Local\Programs\Python\Python35\lib\concurrent\futures\thread.py", line 55, in run
    result = self.fn(*self.args, **self.kwargs)
  File "scraper_nbareference_multiprocess.py", line 151, in scrapy_regular_team_data
    raise Exception(e)
Exception: [WinError 2] The system cannot find the file specified: 'data/regular_season_team_data_2012.csv'
2017-08-13 21:32:02  concurrent.futures ERROR      exception calling callback for <Future at 0x2211249d438 state=finished raised Exception>
Traceback (most recent call last):
  File "scraper_nbareference_multiprocess.py", line 124, in scrapy_regular_team_data
    if os.stat(file).st_size == 0:
FileNotFoundError: [WinError 2] The system cannot find the file specified: 'data/regular_season_team_data_2012.csv'

During handling of the above exception, another exception occurred:

Traceback (most recent call last):
  File "C:\Users\xiyang\AppData\Local\Programs\Python\Python35\lib\concurrent\futures\_base.py", line 297, in _invoke_callbacks
    callback(self)
  File "scraper_nbareference_multiprocess.py", line 158, in output_regular_team_data
    data, games, season = future.result()
  File "C:\Users\xiyang\AppData\Local\Programs\Python\Python35\lib\concurrent\futures\_base.py", line 398, in result
    return self.__get_result()
  File "C:\Users\xiyang\AppData\Local\Programs\Python\Python35\lib\concurrent\futures\_base.py", line 357, in __get_result
    raise self._exception
  File "C:\Users\xiyang\AppData\Local\Programs\Python\Python35\lib\concurrent\futures\thread.py", line 55, in run
    result = self.fn(*self.args, **self.kwargs)
  File "scraper_nbareference_multiprocess.py", line 151, in scrapy_regular_team_data
    raise Exception(e)
Exception: [WinError 2] The system cannot find the file specified: 'data/regular_season_team_data_2012.csv'
2017-08-13 21:32:03  concurrent.futures ERROR      exception calling callback for <Future at 0x2211249d4e0 state=finished raised Exception>
Traceback (most recent call last):
  File "scraper_nbareference_multiprocess.py", line 124, in scrapy_regular_team_data
    if os.stat(file).st_size == 0:
FileNotFoundError: [WinError 2] The system cannot find the file specified: 'data/regular_season_team_data_2012.csv'

During handling of the above exception, another exception occurred:

Traceback (most recent call last):
  File "C:\Users\xiyang\AppData\Local\Programs\Python\Python35\lib\concurrent\futures\_base.py", line 297, in _invoke_callbacks
    callback(self)
  File "scraper_nbareference_multiprocess.py", line 158, in output_regular_team_data
    data, games, season = future.result()
  File "C:\Users\xiyang\AppData\Local\Programs\Python\Python35\lib\concurrent\futures\_base.py", line 398, in result
    return self.__get_result()
  File "C:\Users\xiyang\AppData\Local\Programs\Python\Python35\lib\concurrent\futures\_base.py", line 357, in __get_result
    raise self._exception
  File "C:\Users\xiyang\AppData\Local\Programs\Python\Python35\lib\concurrent\futures\thread.py", line 55, in run
    result = self.fn(*self.args, **self.kwargs)
  File "scraper_nbareference_multiprocess.py", line 151, in scrapy_regular_team_data
    raise Exception(e)
Exception: [WinError 2] The system cannot find the file specified: 'data/regular_season_team_data_2012.csv'
2017-08-13 21:32:04  concurrent.futures ERROR      exception calling callback for <Future at 0x2211415f128 state=finished raised Exception>
Traceback (most recent call last):
  File "scraper_nbareference_multiprocess.py", line 124, in scrapy_regular_team_data
    if os.stat(file).st_size == 0:
FileNotFoundError: [WinError 2] The system cannot find the file specified: 'data/regular_season_team_data_2013.csv'

During handling of the above exception, another exception occurred:

Traceback (most recent call last):
  File "C:\Users\xiyang\AppData\Local\Programs\Python\Python35\lib\concurrent\futures\_base.py", line 297, in _invoke_callbacks
    callback(self)
  File "scraper_nbareference_multiprocess.py", line 158, in output_regular_team_data
    data, games, season = future.result()
  File "C:\Users\xiyang\AppData\Local\Programs\Python\Python35\lib\concurrent\futures\_base.py", line 398, in result
    return self.__get_result()
  File "C:\Users\xiyang\AppData\Local\Programs\Python\Python35\lib\concurrent\futures\_base.py", line 357, in __get_result
    raise self._exception
  File "C:\Users\xiyang\AppData\Local\Programs\Python\Python35\lib\concurrent\futures\thread.py", line 55, in run
    result = self.fn(*self.args, **self.kwargs)
  File "scraper_nbareference_multiprocess.py", line 151, in scrapy_regular_team_data
    raise Exception(e)
Exception: [WinError 2] The system cannot find the file specified: 'data/regular_season_team_data_2013.csv'
2017-08-13 21:32:05  concurrent.futures ERROR      exception calling callback for <Future at 0x2211415f1d0 state=finished raised Exception>
Traceback (most recent call last):
  File "scraper_nbareference_multiprocess.py", line 124, in scrapy_regular_team_data
    if os.stat(file).st_size == 0:
FileNotFoundError: [WinError 2] The system cannot find the file specified: 'data/regular_season_team_data_2013.csv'

During handling of the above exception, another exception occurred:

Traceback (most recent call last):
  File "C:\Users\xiyang\AppData\Local\Programs\Python\Python35\lib\concurrent\futures\_base.py", line 297, in _invoke_callbacks
    callback(self)
  File "scraper_nbareference_multiprocess.py", line 158, in output_regular_team_data
    data, games, season = future.result()
  File "C:\Users\xiyang\AppData\Local\Programs\Python\Python35\lib\concurrent\futures\_base.py", line 398, in result
    return self.__get_result()
  File "C:\Users\xiyang\AppData\Local\Programs\Python\Python35\lib\concurrent\futures\_base.py", line 357, in __get_result
    raise self._exception
  File "C:\Users\xiyang\AppData\Local\Programs\Python\Python35\lib\concurrent\futures\thread.py", line 55, in run
    result = self.fn(*self.args, **self.kwargs)
  File "scraper_nbareference_multiprocess.py", line 151, in scrapy_regular_team_data
    raise Exception(e)
Exception: [WinError 2] The system cannot find the file specified: 'data/regular_season_team_data_2013.csv'
2017-08-13 21:32:06  concurrent.futures ERROR      exception calling callback for <Future at 0x2211415f278 state=finished raised Exception>
Traceback (most recent call last):
  File "scraper_nbareference_multiprocess.py", line 124, in scrapy_regular_team_data
    if os.stat(file).st_size == 0:
FileNotFoundError: [WinError 2] The system cannot find the file specified: 'data/regular_season_team_data_2013.csv'

During handling of the above exception, another exception occurred:

Traceback (most recent call last):
  File "C:\Users\xiyang\AppData\Local\Programs\Python\Python35\lib\concurrent\futures\_base.py", line 297, in _invoke_callbacks
    callback(self)
  File "scraper_nbareference_multiprocess.py", line 158, in output_regular_team_data
    data, games, season = future.result()
  File "C:\Users\xiyang\AppData\Local\Programs\Python\Python35\lib\concurrent\futures\_base.py", line 398, in result
    return self.__get_result()
  File "C:\Users\xiyang\AppData\Local\Programs\Python\Python35\lib\concurrent\futures\_base.py", line 357, in __get_result
    raise self._exception
  File "C:\Users\xiyang\AppData\Local\Programs\Python\Python35\lib\concurrent\futures\thread.py", line 55, in run
    result = self.fn(*self.args, **self.kwargs)
  File "scraper_nbareference_multiprocess.py", line 151, in scrapy_regular_team_data
    raise Exception(e)
Exception: [WinError 2] The system cannot find the file specified: 'data/regular_season_team_data_2013.csv'
2017-08-13 21:32:07  concurrent.futures ERROR      exception calling callback for <Future at 0x2211415f080 state=finished raised Exception>
Traceback (most recent call last):
  File "scraper_nbareference_multiprocess.py", line 124, in scrapy_regular_team_data
    if os.stat(file).st_size == 0:
FileNotFoundError: [WinError 2] The system cannot find the file specified: 'data/regular_season_team_data_2013.csv'

During handling of the above exception, another exception occurred:

Traceback (most recent call last):
  File "C:\Users\xiyang\AppData\Local\Programs\Python\Python35\lib\concurrent\futures\_base.py", line 297, in _invoke_callbacks
    callback(self)
  File "scraper_nbareference_multiprocess.py", line 158, in output_regular_team_data
    data, games, season = future.result()
  File "C:\Users\xiyang\AppData\Local\Programs\Python\Python35\lib\concurrent\futures\_base.py", line 398, in result
    return self.__get_result()
  File "C:\Users\xiyang\AppData\Local\Programs\Python\Python35\lib\concurrent\futures\_base.py", line 357, in __get_result
    raise self._exception
  File "C:\Users\xiyang\AppData\Local\Programs\Python\Python35\lib\concurrent\futures\thread.py", line 55, in run
    result = self.fn(*self.args, **self.kwargs)
  File "scraper_nbareference_multiprocess.py", line 151, in scrapy_regular_team_data
    raise Exception(e)
Exception: [WinError 2] The system cannot find the file specified: 'data/regular_season_team_data_2013.csv'
2017-08-13 21:32:08  concurrent.futures ERROR      exception calling callback for <Future at 0x2211415f320 state=finished raised Exception>
Traceback (most recent call last):
  File "scraper_nbareference_multiprocess.py", line 124, in scrapy_regular_team_data
    if os.stat(file).st_size == 0:
FileNotFoundError: [WinError 2] The system cannot find the file specified: 'data/regular_season_team_data_2013.csv'

During handling of the above exception, another exception occurred:

Traceback (most recent call last):
  File "C:\Users\xiyang\AppData\Local\Programs\Python\Python35\lib\concurrent\futures\_base.py", line 297, in _invoke_callbacks
    callback(self)
  File "scraper_nbareference_multiprocess.py", line 158, in output_regular_team_data
    data, games, season = future.result()
  File "C:\Users\xiyang\AppData\Local\Programs\Python\Python35\lib\concurrent\futures\_base.py", line 398, in result
    return self.__get_result()
  File "C:\Users\xiyang\AppData\Local\Programs\Python\Python35\lib\concurrent\futures\_base.py", line 357, in __get_result
    raise self._exception
  File "C:\Users\xiyang\AppData\Local\Programs\Python\Python35\lib\concurrent\futures\thread.py", line 55, in run
    result = self.fn(*self.args, **self.kwargs)
  File "scraper_nbareference_multiprocess.py", line 151, in scrapy_regular_team_data
    raise Exception(e)
Exception: [WinError 2] The system cannot find the file specified: 'data/regular_season_team_data_2013.csv'
2017-08-13 21:32:09  concurrent.futures ERROR      exception calling callback for <Future at 0x2211415f3c8 state=finished raised Exception>
Traceback (most recent call last):
  File "scraper_nbareference_multiprocess.py", line 124, in scrapy_regular_team_data
    if os.stat(file).st_size == 0:
FileNotFoundError: [WinError 2] The system cannot find the file specified: 'data/regular_season_team_data_2013.csv'

During handling of the above exception, another exception occurred:

Traceback (most recent call last):
  File "C:\Users\xiyang\AppData\Local\Programs\Python\Python35\lib\concurrent\futures\_base.py", line 297, in _invoke_callbacks
    callback(self)
  File "scraper_nbareference_multiprocess.py", line 158, in output_regular_team_data
    data, games, season = future.result()
  File "C:\Users\xiyang\AppData\Local\Programs\Python\Python35\lib\concurrent\futures\_base.py", line 398, in result
    return self.__get_result()
  File "C:\Users\xiyang\AppData\Local\Programs\Python\Python35\lib\concurrent\futures\_base.py", line 357, in __get_result
    raise self._exception
  File "C:\Users\xiyang\AppData\Local\Programs\Python\Python35\lib\concurrent\futures\thread.py", line 55, in run
    result = self.fn(*self.args, **self.kwargs)
  File "scraper_nbareference_multiprocess.py", line 151, in scrapy_regular_team_data
    raise Exception(e)
Exception: [WinError 2] The system cannot find the file specified: 'data/regular_season_team_data_2013.csv'
2017-08-13 21:32:10  concurrent.futures ERROR      exception calling callback for <Future at 0x2211415f470 state=finished raised Exception>
Traceback (most recent call last):
  File "scraper_nbareference_multiprocess.py", line 124, in scrapy_regular_team_data
    if os.stat(file).st_size == 0:
FileNotFoundError: [WinError 2] The system cannot find the file specified: 'data/regular_season_team_data_2013.csv'

During handling of the above exception, another exception occurred:

Traceback (most recent call last):
  File "C:\Users\xiyang\AppData\Local\Programs\Python\Python35\lib\concurrent\futures\_base.py", line 297, in _invoke_callbacks
    callback(self)
  File "scraper_nbareference_multiprocess.py", line 158, in output_regular_team_data
    data, games, season = future.result()
  File "C:\Users\xiyang\AppData\Local\Programs\Python\Python35\lib\concurrent\futures\_base.py", line 398, in result
    return self.__get_result()
  File "C:\Users\xiyang\AppData\Local\Programs\Python\Python35\lib\concurrent\futures\_base.py", line 357, in __get_result
    raise self._exception
  File "C:\Users\xiyang\AppData\Local\Programs\Python\Python35\lib\concurrent\futures\thread.py", line 55, in run
    result = self.fn(*self.args, **self.kwargs)
  File "scraper_nbareference_multiprocess.py", line 151, in scrapy_regular_team_data
    raise Exception(e)
Exception: [WinError 2] The system cannot find the file specified: 'data/regular_season_team_data_2013.csv'
